Traceback (most recent call last):
  File "/home/sheepy/mybook/lib/python3.10/site-packages/jupyter_cache/executors/utils.py", line 58, in single_nb_execution
    executenb(
  File "/home/sheepy/mybook/lib/python3.10/site-packages/nbclient/client.py", line 1314, in execute
    return NotebookClient(nb=nb, resources=resources, km=km, **kwargs).execute()
  File "/home/sheepy/mybook/lib/python3.10/site-packages/jupyter_core/utils/__init__.py", line 165, in wrapped
    return loop.run_until_complete(inner)
  File "/usr/lib/python3.10/asyncio/base_events.py", line 649, in run_until_complete
    return future.result()
  File "/home/sheepy/mybook/lib/python3.10/site-packages/nbclient/client.py", line 709, in async_execute
    await self.async_execute_cell(
  File "/home/sheepy/mybook/lib/python3.10/site-packages/nbclient/client.py", line 1062, in async_execute_cell
    await self._check_raise_for_error(cell, cell_index, exec_reply)
  File "/home/sheepy/mybook/lib/python3.10/site-packages/nbclient/client.py", line 918, in _check_raise_for_error
    raise CellExecutionError.from_cell_and_msg(cell, exec_reply_content)
nbclient.exceptions.CellExecutionError: An error occurred while executing the following cell:
------------------
for(int t=0;t!=-1;){                                  // put the used nodes in linked list in stack (LIFO)
    strt=add_to_list_normal(strt_arr[t].num,t,strt);
    t=strt_arr[t].num;
}
for(int t=0;t!=-1;){                                   // put the used nodes in linked list in stack
    result=add_to_list_normal(result_arr[t].num,t,result);
    t=result_arr[t].num;
}
------------------


[0;36m  Cell [0;32mIn[1], line 1[0;36m[0m
[0;31m    for(int t=0;t!=-1;){                                  // put the used nodes in linked list in stack (LIFO)[0m
[0m        ^[0m
[0;31mSyntaxError[0m[0;31m:[0m invalid syntax. Perhaps you forgot a comma?


